Workbook
Name AnneeComptable: 'Tableau de bord'!$C$6

Sheet Tutoriel
B2: TUTORIEL — Comptabilité NOVA
B3: Mode d'emploi à destination du Trésorier de l'Association NOVA
B4: À lire impérativement avant la première saisie. Conforme au T.T.E. — Chapitres IV et VIII.
B6: 1. À QUOI SERT CE FICHIER ?
B7: Ce fichier est l'outil de comptabilité interne de l'Association NOVA. Il sert à :
B8: • enregistrer toutes les opérations financières (recettes et dépenses) au fil de l'eau ;
B9: • calculer automatiquement le résultat fiscal hebdomadaire (à reporter sur le site IRS chaque Mardi) ;
B10: • surveiller le plafond légal de 50 000 $ HORS DONS sur 4 semaines (Art. 8-1.4 T.T.E.) ;
B11: • conserver une comptabilité régulière, opposable en cas de contrôle (Art. 4-5.2 T.T.E.).
B13: 2. LES 4 FEUILLES DU FICHIER
B14: Feuille | C14: À quoi elle sert | E14: Qui la remplit ?
B15: Tableau de bord | C15: Vue d'ensemble annuelle (KPI, statut plafond) | E15: Auto — sélectionne juste l'année
B16: Saisie | C16: Journal de toutes les opérations de l'année | E16: TOI (le Trésorier) — au fil de l'eau
B17: Suivi hebdo | C17: Récap auto par semaine + calcul fiscal | E17: Auto — formules SUMIFS
B18: Référence T.T.E. | C18: Articles applicables, en consultation | E18: Lecture seule
B20: 3. WORKFLOW HEBDOMADAIRE (À MÉMORISER)
B21: Le T.T.E. impose un calendrier strict (Art. 4-3.3 et 4-3.4). Voici le rituel à respecter chaque semaine :
B22: LUNDI → DIMANCHE | C22: Saisir au fur et à mesure dans la feuille « Saisie » chaque opération de la semaine. Date, type, libellé, montant.
B23: DIMANCHE soir | C23: Vérification finale : toutes les opérations de la semaine sont-elles saisies ? Toutes les pièces justificatives sont-elles archivées ?
B24: LUNDI | C24: Le suivi hebdo est figé pour la semaine écoulée. Aller voir la ligne de la semaine (colonne « Sem. »).
B25: MARDI avant 21h | C25: DÉCLARATION FISCALE sur le site de l'IRS. Reporter : CA hebdo, Résultat imposable, Tranche, Impôt.
B26: MERCREDI avant 21h | C26: PAIEMENT de l'impôt sur le site de l'IRS. Conserver le justificatif de paiement.
B27: Dès Jeudi | C27: Saisir les nouvelles opérations de la semaine en cours.
B29: 4. COMMENT SAISIR UNE OPÉRATION (PAS À PAS)
B30: Pour chaque opération financière (recette ou dépense), tu vas dans la feuille « Saisie » et tu remplis une nouvelle ligne :
B31: 1. | C31: Date | D31: Date exacte de l'opération (jj/mm/aaaa).
B32: — | C32: Année | D32: AUTO — calculée depuis la Date. Colonne grisée. NE PAS REMPLIR.
B33: — | C33: Semaine | D33: AUTO — calculée depuis la Date (semaine ISO 8601, lundi au dimanche). Colonne grisée. NE PAS REMPLIR.
B34: 2. | C34: Type | D34: Choisir DANS LA LISTE DÉROULANTE (cf. Section 5 ci-dessous pour le bon choix).
B35: 3. | C35: Catégorie | D35: Précision libre (ex. « Avocat », « Restaurant », « Visibilité partenaire »). Aide à filtrer.
B36: 4. | C36: Libellé | D36: Description courte et claire (ex. « Honoraires Maître Dupont — rédaction contrats »).
B37: 5. | C37: Montant | D37: Montant TTC en dollars. Toujours positif. C'est le « type » qui indique recette ou dépense.
B39: 5. LES 6 TYPES D'OPÉRATIONS (LE PLUS IMPORTANT)
B40: Bien choisir le TYPE est CRITIQUE : c'est ce qui détermine si l'opération est imposable et si elle compte dans le plafond 50k$.
B41: Type | C41: Quand l'utiliser | D41: Imposable ? | E41: Compte plafond 50k$ ?
B42: don | C42: Apport SANS contrepartie commerciale (numéraire ou nature) | D42: NON | E42: NON (hors plafond — Art. 8-1.4)
B43: subvention | C43: Apport public (Gouverneur, État, autre institution) | D43: NON (Art. 4-2.16) | E43: OUI
B44: prestation | C44: Partenariat AVEC contrepartie (logo, mention, visibilité) | D44: OUI | E44: OUI
B45: autre | C45: Bénéfice direct d'événement (billetterie, vente annexe) | D45: OUI (Art. 4-2.2) | E45: OUI
B46: charge_deductible | C46: Dépense admise en déduction (avocat, production, etc.) | D46: (réduit le résultat imposable) | E46: —
...

Sheet Tableau de bord
B2: NOVA
B3: Nouvelle Organisation Vie Associative — État de San Andreas
B4: Comptabilité associative — Conforme au T.T.E. (Chap. IV & VIII)
B6: Année comptable | C6: 2026
B9: Total dons (annuel) | C9: Total subventions | D9: Chiffre d'affaires annuel | E9: Total dépenses
B10: ==SUMIFS(Saisie!G:G,Saisie!B:B,C6,Saisie!D:D,"don") | C10: ==SUMIFS(Saisie!G:G,Saisie!B:B,C6,Saisie!D:D,"subvention") | D10: ==SUMIFS(Saisie!G:G,Saisie!B:B,C6,Saisie!D:D,"prestation")+SUMIFS(Saisie!G:G,Saisie!B:B,C6,Saisie!D:D,"autre") | E10: ==SUMIFS(Saisie!G:G,Saisie!B:B,C6,Saisie!D:D,"charge_deductible")+SUMIFS(Saisie!G:G,Saisie!B:B,C6,Saisie!D:D,"charge_non_deductible")
B11: Hors plafond — Art. 8-1.4 | C11: Non imposables — Art. 4-2.16 | D11: Prestations + autres entrées | E11: Toutes catégories
B14: SUIVI DU PLAFOND ASSOCIATIF — Article 8-1.4 du T.T.E.
B15: Plafond légal : | C15: 50000
B16: Cumul max sur 4 semaines (année) : | C16: ==MAX('Suivi hebdo'!O5:O56)
B17: Statut : | C17: ==IF(C16>50000,"⚠ DÉPASSEMENT — risque de retrait du statut",IF(C16>40000,"⚠ VIGILANCE — > 80% du plafond","✓ Conforme"))
B19: MODE D'EMPLOI
B20: 1. Saisir l'année dans la cellule jaune ci-dessus (C6).
B21: 2. Aller dans la feuille « Saisie » et enregistrer toutes les opérations de la semaine (date, type, catégorie, libellé, montant).
B22: 3. La feuille « Suivi hebdo » se met à jour automatiquement (formules SUMIFS et calcul fiscal selon les tranches T.T.E.).
B23: 4. Vérifier la colonne « Statut plafond » : si DÉPASSEMENT pendant 4 semaines consécutives, risque de retrait du statut associatif (Art. 8-1.4).
B24: 5. Pour chaque déclaration fiscale (Mardi avant 21h sur le site de l'IRS), reporter les valeurs de la ligne « Suivi hebdo » correspondante.
B25: 6. Conserver toutes les pièces justificatives (Art. 4-5.2). Sanctions sévères en cas de comptabilité irrégulière (jusqu'à saisie 50% du compte sur le gérant).

Sheet Saisie
A1: NOVA — Journal des opérations comptables
A2: ⚠ Saisir UNIQUEMENT les colonnes Date / Type / Catégorie / Libellé / Montant. Les colonnes grisées « Année » et « Semaine » sont calculées automatiquement à partir de la Date — NE PAS LES MODIFIER.
A4: Date | B4: Année | C4: Semaine | D4: Type | E4: Catégorie | F4: Libellé | G4: Montant
B5: =IF(A5="","",YEAR(A5)) | C5: =IF(A5="","",WEEKNUM(A5,21))
B6: =IF(A6="","",YEAR(A6)) | C6: =IF(A6="","",WEEKNUM(A6,21))
B7: =IF(A7="","",YEAR(A7)) | C7: =IF(A7="","",WEEKNUM(A7,21))
B8: =IF(A8="","",YEAR(A8)) | C8: =IF(A8="","",WEEKNUM(A8,21))
B9: =IF(A9="","",YEAR(A9)) | C9: =IF(A9="","",WEEKNUM(A9,21))
B10: =IF(A10="","",YEAR(A10)) | C10: =IF(A10="","",WEEKNUM(A10,21))
B11: =IF(A11="","",YEAR(A11)) | C11: =IF(A11="","",WEEKNUM(A11,21))
B12: =IF(A12="","",YEAR(A12)) | C12: =IF(A12="","",WEEKNUM(A12,21))
B13: =IF(A13="","",YEAR(A13)) | C13: =IF(A13="","",WEEKNUM(A13,21))
B14: =IF(A14="","",YEAR(A14)) | C14: =IF(A14="","",WEEKNUM(A14,21))
B15: =IF(A15="","",YEAR(A15)) | C15: =IF(A15="","",WEEKNUM(A15,21))
B16: =IF(A16="","",YEAR(A16)) | C16: =IF(A16="","",WEEKNUM(A16,21))
... B204: =IF(A204="","",YEAR(A204)) | C204: =IF(A204="","",WEEKNUM(A204,21))

Sheet Suivi hebdo
A1: NOVA — Suivi comptable hebdomadaire
A2: Année : | C2: =='Tableau de bord'!C6 | D2: Calculs automatiques basés sur la feuille « Saisie ». Tranches d'imposition selon Art. 4-3.2 du T.T.E.
A4: Sem. | B4: Dons | C4: Subventions | D4: Prestations | E4: Autres entrées | F4: Charges déduct. | G4: Charges non-déduct. | H4: CA hebdo | I4: Résultat impos. | J4: Tranche | K4: Taux | L4: Impôt à payer | M4: Hors dons (sem.) | N4: Cumul 4 sem. | O4: Statut plafond
A5: 1 | B5: ==SUMIFS(Saisie!$G:$G,Saisie!$B:$B,$C$2,Saisie!$C:$C,$A5,Saisie!$D:$D,"don") | C5: ==SUMIFS(Saisie!$G:$G,Saisie!$B:$B,$C$2,Saisie!$C:$C,$A5,Saisie!$D:$D,"subvention") | D5: ==SUMIFS(Saisie!$G:$G,Saisie!$B:$B,$C$2,Saisie!$C:$C,$A5,Saisie!$D:$D,"prestation") | E5: ==SUMIFS(Saisie!$G:$G,Saisie!$B:$B,$C$2,Saisie!$C:$C,$A5,Saisie!$D:$D,"autre") | F5: ==SUMIFS(Saisie!$G:$G,Saisie!$B:$B,$C$2,Saisie!$C:$C,$A5,Saisie!$D:$D,"charge_deductible") | G5: ==SUMIFS(Saisie!$G:$G,Saisie!$B:$B,$C$2,Saisie!$C:$C,$A5,Saisie!$D:$D,"charge_non_deductible") | H5: ==D5+E5 | I5: ==H5-F5 | J5: ==IF(H5>500000,5,IF(H5>250000,4,IF(H5>100000,3,IF(H5>50000,2,IF(H5>10000,1,0))))) | K5: ==CHOOSE(J5+1,0,0.1,0.19,0.28,0.36,0.46) | L5: ==MAX(0,I5*K5) | M5: ==H5+C5 | N5: ==SUM(OFFSET($M$5,MAX(0,ROW()-8),0,MIN(4,ROW()-4),1)) | O5: ==IF(N5>50000,"⚠ DÉPASSEMENT",IF(N5>40000,"⚠ VIGILANCE","✓ OK"))
A6: 2 | B6: ==SUMIFS(Saisie!$G:$G,Saisie!$B:$B,$C$2,Saisie!$C:$C,$A6,Saisie!$D:$D,"don") | C6: ==SUMIFS(Saisie!$G:$G,Saisie!$B:$B,$C$2,Saisie!$C:$C,$A6,Saisie!$D:$D,"subvention") | D6: ==SUMIFS(Saisie!$G:$G,Saisie!$B:$B,$C$2,Saisie!$C:$C,$A6,Saisie!$D:$D,"prestation") | E6: ==SUMIFS(Saisie!$G:$G,Saisie!$B:$B,$C$2,Saisie!$C:$C,$A6,Saisie!$D:$D,"autre") | F6: ==SUMIFS(Saisie!$G:$G,Saisie!$B:$B,$C$2,Saisie!$C:$C,$A6,Saisie!$D:$D,"charge_deductible") | G6: ==SUMIFS(Saisie!$G:$G,Saisie!$B:$B,$C$2,Saisie!$C:$C,$A6,Saisie!$D:$D,"charge_non_deductible") | H6: ==D6+E6 | I6: ==H6-F6 | J6: ==IF(H6>500000,5,IF(H6>250000,4,IF(H6>100000,3,IF(H6>50000,2,IF(H6>10000,1,0))))) | K6: ==CHOOSE(J6+1,0,0.1,0.19,0.28,0.36,0.46) | L6: ==MAX(0,I6*K6) | M6: ==H6+C6 | N6: ==SUM(OFFSET($M$5,MAX(0,ROW()-8),0,MIN(4,ROW()-4),1)) | O6: ==IF(N6>50000,"⚠ DÉPASSEMENT",IF(N6>40000,"⚠ VIGILANCE","✓ OK"))
A7: 3 | B7: ==SUMIFS(Saisie!$G:$G,Saisie!$B:$B,$C$2,Saisie!$C:$C,$A7,Saisie!$D:$D,"don") | C7: ==SUMIFS(Saisie!$G:$G,Saisie!$B:$B,$C$2,Saisie!$C:$C,$A7,Saisie!$D:$D,"subvention") | D7: ==SUMIFS(Saisie!$G:$G,Saisie!$B:$B,$C$2,Saisie!$C:$C,$A7,Saisie!$D:$D,"prestation") | E7: ==SUMIFS(Saisie!$G:$G,Saisie!$B:$B,$C$2,Saisie!$C:$C,$A7,Saisie!$D:$D,"autre") | F7: ==SUMIFS(Saisie!$G:$G,Saisie!$B:$B,$C$2,Saisie!$C:$C,$A7,Saisie!$D:$D,"charge_deductible") | G7: ==SUMIFS(Saisie!$G:$G,Saisie!$B:$B,$C$2,Saisie!$C:$C,$A7,Saisie!$D:$D,"charge_non_deductible") | H7: ==D7+E7 | I7: ==H7-F7 | J7: ==IF(H7>500000,5,IF(H7>250000,4,IF(H7>100000,3,IF(H7>50000,2,IF(H7>10000,1,0))))) | K7: ==CHOOSE(J7+1,0,0.1,0.19,0.28,0.36,0.46) | L7: ==MAX(0,I7*K7) | M7: ==H7+C7 | N7: ==SUM(OFFSET($M$5,MAX(0,ROW()-8),0,MIN(4,ROW()-4),1)) | O7: ==IF(N7>50000,"⚠ DÉPASSEMENT",IF(N7>40000,"⚠ VIGILANCE","✓ OK"))
A8: 4 | B8: ==SUMIFS(Saisie!$G:$G,Saisie!$B:$B,$C$2,Saisie!$C:$C,$A8,Saisie!$D:$D,"don") | C8: ==SUMIFS(Saisie!$G:$G,Saisie!$B:$B,$C$2,Saisie!$C:$C,$A8,Saisie!$D:$D,"subvention") | D8: ==SUMIFS(Saisie!$G:$G,Saisie!$B:$B,$C$2,Saisie!$C:$C,$A8,Saisie!$D:$D,"prestation") | E8: ==SUMIFS(Saisie!$G:$G,Saisie!$B:$B,$C$2,Saisie!$C:$C,$A8,Saisie!$D:$D,"autre") | F8: ==SUMIFS(Saisie!$G:$G,Saisie!$B:$B,$C$2,Saisie!$C:$C,$A8,Saisie!$D:$D,"charge_deductible") | G8: ==SUMIFS(Saisie!$G:$G,Saisie!$B:$B,$C$2,Saisie!$C:$C,$A8,Saisie!$D:$D,"charge_non_deductible") | H8: ==D8+E8 | I8: ==H8-F8 | J8: ==IF(H8>500000,5,IF(H8>250000,4,IF(H8>100000,3,IF(H8>50000,2,IF(H8>10000,1,0))))) | K8: ==CHOOSE(J8+1,0,0.1,0.19,0.28,0.36,0.46) | L8: ==MAX(0,I8*K8) | M8: ==H8+C8 | N8: ==SUM(OFFSET($M$5,MAX(0,ROW()-8),0,MIN(4,ROW()-4),1)) | O8: ==IF(N8>50000,"⚠ DÉPASSEMENT",IF(N8>40000,"⚠ VIGILANCE","✓ OK"))
A9: 5 | B9: ==SUMIFS(Saisie!$G:$G,Saisie!$B:$B,$C$2,Saisie!$C:$C,$A9,Saisie!$D:$D,"don") | C9: ==SUMIFS(Saisie!$G:$G,Saisie!$B:$B,$C$2,Saisie!$C:$C,$A9,Saisie!$D:$D,"subvention") | D9: ==SUMIFS(Saisie!$G:$G,Saisie!$B:$B,$C$2,Saisie!$C:$C,$A9,Saisie!$D:$D,"prestation") | E9: ==SUMIFS(Saisie!$G:$G,Saisie!$B:$B,$C$2,Saisie!$C:$C,$A9,Saisie!$D:$D,"autre") | F9: ==SUMIFS(Saisie!$G:$G,Saisie!$B:$B,$C$2,Saisie!$C:$C,$A9,Saisie!$D:$D,"charge_deductible") | G9: ==SUMIFS(Saisie!$G:$G,Saisie!$B:$B,$C$2,Saisie!$C:$C,$A9,Saisie!$D:$D,"charge_non_deductible") | H9: ==D9+E9 | I9: ==H9-F9 | J9: ==IF(H9>500000,5,IF(H9>250000,4,IF(H9>100000,3,IF(H9>50000,2,IF(H9>10000,1,0))))) | K9: ==CHOOSE(J9+1,0,0.1,0.19,0.28,0.36,0.46) | L9: ==MAX(0,I9*K9) | M9: ==H9+C9 | N9: ==SUM(OFFSET($M$5,MAX(0,ROW()-8),0,MIN(4,ROW()-4),1)) | O9: ==IF(N9>50000,"⚠ DÉPASSEMENT",IF(N9>40000,"⚠ VIGILANCE","✓ OK"))
A10: 6 | B10: ==SUMIFS(Saisie!$G:$G,Saisie!$B:$B,$C$2,Saisie!$C:$C,$A10,Saisie!$D:$D,"don") | C10: ==SUMIFS(Saisie!$G:$G,Saisie!$B:$B,$C$2,Saisie!$C:$C,$A10,Saisie!$D:$D,"subvention") | D10: ==SUMIFS(Saisie!$G:$G,Saisie!$B:$B,$C$2,Saisie!$C:$C,$A10,Saisie!$D:$D,"prestation") | E10: ==SUMIFS(Saisie!$G:$G,Saisie!$B:$B,$C$2,Saisie!$C:$C,$A10,Saisie!$D:$D,"autre") | F10: ==SUMIFS(Saisie!$G:$G,Saisie!$B:$B,$C$2,Saisie!$C:$C,$A10,Saisie!$D:$D,"charge_deductible") | G10: ==SUMIFS(Saisie!$G:$G,Saisie!$B:$B,$C$2,Saisie!$C:$C,$A10,Saisie!$D:$D,"charge_non_deductible") | H10: ==D10+E10 | I10: ==H10-F10 | J10: ==IF(H10>500000,5,IF(H10>250000,4,IF(H10>100000,3,IF(H10>50000,2,IF(H10>10000,1,0))))) | K10: ==CHOOSE(J10+1,0,0.1,0.19,0.28,0.36,0.46) | L10: ==MAX(0,I10*K10) | M10: ==H10+C10 | N10: ==SUM(OFFSET($M$5,MAX(0,ROW()-8),0,MIN(4,ROW()-4),1)) | O10: ==IF(N10>50000,"⚠ DÉPASSEMENT",IF(N10>40000,"⚠ VIGILANCE","✓ OK"))
A11: 7 | B11: ==SUMIFS(Saisie!$G:$G,Saisie!$B:$B,$C$2,Saisie!$C:$C,$A11,Saisie!$D:$D,"don") | C11: ==SUMIFS(Saisie!$G:$G,Saisie!$B:$B,$C$2,Saisie!$C:$C,$A11,Saisie!$D:$D,"subvention") | D11: ==SUMIFS(Saisie!$G:$G,Saisie!$B:$B,$C$2,Saisie!$C:$C,$A11,Saisie!$D:$D,"prestation") | E11: ==SUMIFS(Saisie!$G:$G,Saisie!$B:$B,$C$2,Saisie!$C:$C,$A11,Saisie!$D:$D,"autre") | F11: ==SUMIFS(Saisie!$G:$G,Saisie!$B:$B,$C$2,Saisie!$C:$C,$A11,Saisie!$D:$D,"charge_deductible") | G11: ==SUMIFS(Saisie!$G:$G,Saisie!$B:$B,$C$2,Saisie!$C:$C,$A11,Saisie!$D:$D,"charge_non_deductible") | H11: ==D11+E11 | I11: ==H11-F11 | J11: ==IF(H11>500000,5,IF(H11>250000,4,IF(H11>100000,3,IF(H11>50000,2,IF(H11>10000,1,0))))) | K11: ==CHOOSE(J11+1,0,0.1,0.19,0.28,0.36,0.46) | L11: ==MAX(0,I11*K11) | M11: ==H11+C11 | N11: ==SUM(OFFSET($M$5,MAX(0,ROW()-8),0,MIN(4,ROW()-4),1)) | O11: ==IF(N11>50000,"⚠ DÉPASSEMENT",IF(N11>40000,"⚠ VIGILANCE","✓ OK"))
A12: 8 | B12: ==SUMIFS(Saisie!$G:$G,Saisie!$B:$B,$C$2,Saisie!$C:$C,$A12,Saisie!$D:$D,"don") | C12: ==SUMIFS(Saisie!$G:$G,Saisie!$B:$B,$C$2,Saisie!$C:$C,$A12,Saisie!$D:$D,"subvention") | D12: ==SUMIFS(Saisie!$G:$G,Saisie!$B:$B,$C$2,Saisie!$C:$C,$A12,Saisie!$D:$D,"prestation") | E12: ==SUMIFS(Saisie!$G:$G,Saisie!$B:$B,$C$2,Saisie!$C:$C,$A12,Saisie!$D:$D,"autre") | F12: ==SUMIFS(Saisie!$G:$G,Saisie!$B:$B,$C$2,Saisie!$C:$C,$A12,Saisie!$D:$D,"charge_deductible") | G12: ==SUMIFS(Saisie!$G:$G,Saisie!$B:$B,$C$2,Saisie!$C:$C,$A12,Saisie!$D:$D,"charge_non_deductible") | H12: ==D12+E12 | I12: ==H12-F12 | J12: ==IF(H12>500000,5,IF(H12>250000,4,IF(H12>100000,3,IF(H12>50000,2,IF(H12>10000,1,0))))) | K12: ==CHOOSE(J12+1,0,0.1,0.19,0.28,0.36,0.46) | L12: ==MAX(0,I12*K12) | M12: ==H12+C12 | N12: ==SUM(OFFSET($M$5,MAX(0,ROW()-8),0,MIN(4,ROW()-4),1)) | O12: ==IF(N12>50000,"⚠ DÉPASSEMENT",IF(N12>40000,"⚠ VIGILANCE","✓ OK"))
A13: 9 | B13: ==SUMIFS(Saisie!$G:$G,Saisie!$B:$B,$C$2,Saisie!$C:$C,$A13,Saisie!$D:$D,"don") | C13: ==SUMIFS(Saisie!$G:$G,Saisie!$B:$B,$C$2,Saisie!$C:$C,$A13,Saisie!$D:$D,"subvention") | D13: ==SUMIFS(Saisie!$G:$G,Saisie!$B:$B,$C$2,Saisie!$C:$C,$A13,Saisie!$D:$D,"prestation") | E13: ==SUMIFS(Saisie!$G:$G,Saisie!$B:$B,$C$2,Saisie!$C:$C,$A13,Saisie!$D:$D,"autre") | F13: ==SUMIFS(Saisie!$G:$G,Saisie!$B:$B,$C$2,Saisie!$C:$C,$A13,Saisie!$D:$D,"charge_deductible") | G13: ==SUMIFS(Saisie!$G:$G,Saisie!$B:$B,$C$2,Saisie!$C:$C,$A13,Saisie!$D:$D,"charge_non_deductible") | H13: ==D13+E13 | I13: ==H13-F13 | J13: ==IF(H13>500000,5,IF(H13>250000,4,IF(H13>100000,3,IF(H13>50000,2,IF(H13>10000,1,0))))) | K13: ==CHOOSE(J13+1,0,0.1,0.19,0.28,0.36,0.46) | L13: ==MAX(0,I13*K13) | M13: ==H13+C13 | N13: ==SUM(OFFSET($M$5,MAX(0,ROW()-8),0,MIN(4,ROW()-4),1)) | O13: ==IF(N13>50000,"⚠ DÉPASSEMENT",IF(N13>40000,"⚠ VIGILANCE","✓ OK"))
A14: 10 | B14: ==SUMIFS(Saisie!$G:$G,Saisie!$B:$B,$C$2,Saisie!$C:$C,$A14,Saisie!$D:$D,"don") | C14: ==SUMIFS(Saisie!$G:$G,Saisie!$B:$B,$C$2,Saisie!$C:$C,$A14,Saisie!$D:$D,"subvention") | D14: ==SUMIFS(Saisie!$G:$G,Saisie!$B:$B,$C$2,Saisie!$C:$C,$A14,Saisie!$D:$D,"prestation") | E14: ==SUMIFS(Saisie!$G:$G,Saisie!$B:$B,$C$2,Saisie!$C:$C,$A14,Saisie!$D:$D,"autre") | F14: ==SUMIFS(Saisie!$G:$G,Saisie!$B:$B,$C$2,Saisie!$C:$C,$A14,Saisie!$D:$D,"charge_deductible") | G14: ==SUMIFS(Saisie!$G:$G,Saisie!$B:$B,$C$2,Saisie!$C:$C,$A14,Saisie!$D:$D,"charge_non_deductible") | H14: ==D14+E14 | I14: ==H14-F14 | J14: ==IF(H14>500000,5,IF(H14>250000,4,IF(H14>100000,3,IF(H14>50000,2,IF(H14>10000,1,0))))) | K14: ==CHOOSE(J14+1,0,0.1,0.19,0.28,0.36,0.46) | L14: ==MAX(0,I14*K14) | M14: ==H14+C14 | N14: ==SUM(OFFSET($M$5,MAX(0,ROW()-8),0,MIN(4,ROW()-4),1)) | O14: ==IF(N14>50000,"⚠ DÉPASSEMENT",IF(N14>40000,"⚠ VIGILANCE","✓ OK"))
A15: 11 | B15: ==SUMIFS(Saisie!$G:$G,Saisie!$B:$B,$C$2,Saisie!$C:$C,$A15,Saisie!$D:$D,"don") | C15: ==SUMIFS(Saisie!$G:$G,Saisie!$B:$B,$C$2,Saisie!$C:$C,$A15,Saisie!$D:$D,"subvention") | D15: ==SUMIFS(Saisie!$G:$G,Saisie!$B:$B,$C$2,Saisie!$C:$C,$A15,Saisie!$D:$D,"prestation") | E15: ==SUMIFS(Saisie!$G:$G,Saisie!$B:$B,$C$2,Saisie!$C:$C,$A15,Saisie!$D:$D,"autre") | F15: ==SUMIFS(Saisie!$G:$G,Saisie!$B:$B,$C$2,Saisie!$C:$C,$A15,Saisie!$D:$D,"charge_deductible") | G15: ==SUMIFS(Saisie!$G:$G,Saisie!$B:$B,$C$2,Saisie!$C:$C,$A15,Saisie!$D:$D,"charge_non_deductible") | H15: ==D15+E15 | I15: ==H15-F15 | J15: ==IF(H15>500000,5,IF(H15>250000,4,IF(H15>100000,3,IF(H15>50000,2,IF(H15>10000,1,0))))) | K15: ==CHOOSE(J15+1,0,0.1,0.19,0.28,0.36,0.46) | L15: ==MAX(0,I15*K15) | M15: ==H15+C15 | N15: ==SUM(OFFSET($M$5,MAX(0,ROW()-8),0,MIN(4,ROW()-4),1)) | O15: ==IF(N15>50000,"⚠ DÉPASSEMENT",IF(N15>40000,"⚠ VIGILANCE","✓ OK"))
A16: 12 | B16: ==SUMIFS(Saisie!$G:$G,Saisie!$B:$B,$C$2,Saisie!$C:$C,$A16,Saisie!$D:$D,"don") | C16: ==SUMIFS(Saisie!$G:$G,Saisie!$B:$B,$C$2,Saisie!$C:$C,$A16,Saisie!$D:$D,"subvention") | D16: ==SUMIFS(Saisie!$G:$G,Saisie!$B:$B,$C$2,Saisie!$C:$C,$A16,Saisie!$D:$D,"prestation") | E16: ==SUMIFS(Saisie!$G:$G,Saisie!$B:$B,$C$2,Saisie!$C:$C,$A16,Saisie!$D:$D,"autre") | F16: ==SUMIFS(Saisie!$G:$G,Saisie!$B:$B,$C$2,Saisie!$C:$C,$A16,Saisie!$D:$D,"charge_deductible") | G16: ==SUMIFS(Saisie!$G:$G,Saisie!$B:$B,$C$2,Saisie!$C:$C,$A16,Saisie!$D:$D,"charge_non_deductible") | H16: ==D16+E16 | I16: ==H16-F16 | J16: ==IF(H16>500000,5,IF(H16>250000,4,IF(H16>100000,3,IF(H16>50000,2,IF(H16>10000,1,0))))) | K16: ==CHOOSE(J16+1,0,0.1,0.19,0.28,0.36,0.46) | L16: ==MAX(0,I16*K16) | M16: ==H16+C16 | N16: ==SUM(OFFSET($M$5,MAX(0,ROW()-8),0,MIN(4,ROW()-4),1)) | O16: ==IF(N16>50000,"⚠ DÉPASSEMENT",IF(N16>40000,"⚠ VIGILANCE","✓ OK"))
... A56: 52 | B56: ==SUMIFS(Saisie!$G:$G,Saisie!$B:$B,$C$2,Saisie!$C:$C,$A56,Saisie!$D:$D,"don") | C56: ==SUMIFS(Saisie!$G:$G,Saisie!$B:$B,$C$2,Saisie!$C:$C,$A56,Saisie!$D:$D,"subvention") | D56: ==SUMIFS(Saisie!$G:$G,Saisie!$B:$B,$C$2,Saisie!$C:$C,$A56,Saisie!$D:$D,"prestation") | E56: ==SUMIFS(Saisie!$G:$G,Saisie!$B:$B,$C$2,Saisie!$C:$C,$A56,Saisie!$D:$D,"autre") | F56: ==SUMIFS(Saisie!$G:$G,Saisie!$B:$B,$C$2,Saisie!$C:$C,$A56,Saisie!$D:$D,"charge_deductible") | G56: ==SUMIFS(Saisie!$G:$G,Saisie!$B:$B,$C$2,Saisie!$C:$C,$A56,Saisie!$D:$D,"charge_non_deductible") | H56: ==D56+E56 | I56: ==H56-F56 | J56: ==IF(H56>500000,5,IF(H56>250000,4,IF(H56>100000,3,IF(H56>50000,2,IF(H56>10000,1,0))))) | K56: ==CHOOSE(J56+1,0,0.1,0.19,0.28,0.36,0.46) | L56: ==MAX(0,I56*K56) | M56: ==H56+C56 | N56: ==SUM(OFFSET($M$5,MAX(0,ROW()-8),0,MIN(4,ROW()-4),1)) | O56: ==IF(N56>50000,"⚠ DÉPASSEMENT",IF(N56>40000,"⚠ VIGILANCE","✓ OK"))
A58: TOTAL | B58: ==SUM(B5:B56) | C58: ==SUM(C5:C56) | D58: ==SUM(D5:D56) | E58: ==SUM(E5:E56) | F58: ==SUM(F5:F56) | G58: ==SUM(G5:G56) | H58: ==SUM(H5:H56) | I58: ==SUM(I5:I56) | L58: ==SUM(L5:L56) | M58: ==SUM(M5:M56)

Sheet Référence T.T.E.
B2: Référentiel T.T.E. — Articles applicables à NOVA
B3: Code des Taxes, du Travail et des Entreprises — Serveur FlashFA
B5: CHAPITRE VIII — ASSOCIATIONS
B6: Art. 8-1.1 | C6: Association = but non lucratif obligatoire. Aucune rémunération possible aux responsables ou membres.
B7: Art. 8-1.2 | C7: Déclaration obligatoire auprès de la Vie Civile + officialisation par le Gouvernement de San Andreas.
B8: Art. 8-1.3 | C8: Déclaration des revenus et mouvements monétaires (mêmes obligations que les entreprises).
B9: Art. 8-1.4 | C9: ⚠ PLAFOND : > 50 000 $ HORS DONS sur 4 déclarations consécutives → retrait du statut d'association.
B10: Art. 8-1.5 | C10: Bénévoles = contrat d'engagement associatif obligatoire.
B11: Art. 8-1.6 | C11: Mêmes règles fiscales que les entreprises (Chap. IV).
B12: Art. 8-1.7 | C12: Déductions associatives : 1 garage + 1 stockage 1,5 t (ou bureau) + véhicules à valider IRS.
B14: CHAPITRE IV-II — CALCUL DU RÉSULTAT
B15: Art. 4-2.1 | C15: CA hebdomadaire — semaine = Lundi 00h00 → Dimanche 23h59.
B16: Art. 4-2.2 | C16: Autres entrées incluent les bénéfices liés aux évènements (imposables).
B17: Art. 4-2.4 | C17: Résultat imposable = (CA + Autres entrées) − Charges déductibles.
B18: Art. 4-2.8 | C18: Frais avocat déductibles, max 30 000 $.
B19: Art. 4-2.10 | C19: Nourriture employés déductible, max 750 $/employé.
B20: Art. 4-2.11 | C20: Frais immobilier — déductibilité limitée à certains types d'entreprises. Pour NOVA : à valider IRS (Art. 8-1.7). Sinon amende 4 000 $.
B21: Art. 4-2.12 | C21: Frais véhicule — déductibilité limitée. Pour NOVA : à valider IRS. Sinon amende 4 000 $.
B22: Art. 4-2.16 | C22: ⭐ SUBVENTIONS NON IMPOSABLES (à exploiter via demande au Gouverneur).
B23: Art. 4-2.17 | C23: Section "Dépenses non-déductibles" obligatoire à remplir. Sinon amende 4 000 $.
B25: CHAPITRE IV-III — IMPÔTS
B26: Art. 4-3.1 | C26: Impôts payés chaque semaine sur revenu imposable de la semaine précédente.
B27: Art. 4-3.2 | C27: Tranches : 0% (≤10k$), 10% (10-50k), 19% (50-100k), 28% (100-250k), 36% (250-500k), 46% (>500k).
B28: Art. 4-3.3 | C28: 📅 Déclaration : avant Mardi 21h.
B29: Art. 4-3.4 | C29: 💰 Paiement : avant Mercredi 21h.
B31: CHAPITRE IV-IV — PÉNALITÉS DE RETARD
B32: Art. 4-4.1 | C32: 24h retard +10% | 48h +20% | 72h +30% | 96h +40%.
B34: CHAPITRE IV-V — SANCTIONS
B35: Art. 4-5.1 | C35: Compta inexistante → fermeture administrative + sanctions gérant/co-gérant.
B36: Art. 4-5.2 | C36: Compta irrégulière, 4 paliers d'amende : 5%, 7%, 10%, fermeture. Saisie commune : 50% gérant + 35% co-gérant + 15% matériel.
B37: Art. 4-5.3 | C37: ⚠ Suspicion blanchiment : 72h pour justifier, sinon 45% du compte saisi (65% gérant + 25% co-gérant).
B38: Art. 4-5.4 | C38: 4 semaines de résultat déficitaire → l'État peut remettre la gérance.
